# - 
biomesToSpawnIn=
weight=10
embed_into_distance=1
acceptable_target_blocks=stone,grass,dirt,sand,gravel
dimensions=6,50,50
allowable_overhang=10
max_cut_in=2
cut_in_buffer=0
max_leveling=2
leveling_buffer=1
preserve_water=0
preserve_lava=0
preserve_plants=1

rule1=0,100,preserveBlock
rule2=0,100,
rule3=0,100,
rule4=0,100,
rule5=0,100,
rule6=0,100,
rule7=0,100,
rule8=0,100,
rule9=0,100,

layer
1,1,1,1,1,1,1,1,1,1,1,1,1,1,1,1,1,1,1,1,1,1,1,1,1,1,1,1,1,1,1,1,1,1,1,1,1,1,1,1,1,1,1,1,1,1,1,1,1,1
1,1,1,1,1,1,1,1,1,1,1,1,1,1,1,1,1,1,1,1,1,1,1,1,1,1,1,1,1,1,1,1,1,1,1,1,1,1,1,1,1,1,1,1,1,1,1,1,1,1
1,1,1,1,1,1,1,1,1,1,1,1,1,1,1,1,1,1,1,1,1,1,1,1,1,1,1,1,1,1,1,1,1,1,1,1,1,1,1,1,1,1,1,1,1,1,1,1,1,1
1,1,1,1,1,1,1,1,1,1,1,1,1,1,1,1,1,1,1,1,1,1,1,1,1,1,1,1,1,1,1,1,1,1,1,1,1,1,1,1,1,1,1,1,1,1,1,1,1,1
1,1,1,1,1,1,1,1,1,1,1,1,1,1,1,1,1,1,1,1,1,1,1,1,1,1,1,1,1,1,1,1,1,1,1,1,1,1,1,1,1,1,1,1,1,1,1,1,1,1
1,1,1,1,1,1,1,1,1,1,1,1,1,1,1,1,1,1,1,1,1,1,1,1,1,1,1,1,1,1,1,1,1,1,1,1,1,1,1,1,1,1,1,1,1,1,1,1,1,1
1,1,1,1,1,1,1,1,1,1,1,1,1,1,1,1,1,1,1,1,1,1,1,1,1,1,1,1,1,1,1,1,1,1,1,1,1,1,1,1,1,1,1,1,1,1,1,1,1,1
1,1,1,1,1,1,1,1,1,1,1,1,1,1,1,1,1,1,1,1,1,1,1,1,1,1,1,1,1,1,1,1,1,1,1,1,1,1,1,1,1,1,1,1,1,1,1,1,1,1
1,1,1,1,1,1,1,1,1,1,1,1,1,1,1,1,1,1,1,1,1,1,1,1,1,1,1,1,1,1,1,1,1,1,1,1,1,1,1,1,1,1,1,1,1,1,1,1,1,1
1,1,1,1,1,1,1,1,1,1,1,1,1,1,1,1,1,1,1,1,1,1,1,1,1,1,1,1,1,1,1,1,1,1,1,1,1,1,1,1,1,1,1,1,1,1,1,1,1,1
1,1,1,1,1,1,1,1,1,1,1,1,1,1,1,1,1,1,1,1,1,1,1,1,1,1,1,1,1,1,1,1,1,1,1,1,1,1,1,1,1,1,1,1,1,1,1,1,1,1
1,1,1,1,1,1,1,1,1,1,1,1,1,1,1,1,1,1,1,1,1,1,1,1,1,1,1,1,1,1,1,1,1,1,1,1,1,1,1,1,1,1,1,1,1,1,1,1,1,1
1,1,1,1,1,1,1,1,1,1,1,1,1,1,1,1,1,1,1,1,1,1,1,1,1,1,1,1,1,1,1,1,1,1,1,1,1,1,1,1,1,1,1,1,1,1,1,1,1,1
1,1,1,1,1,1,1,1,1,1,1,1,1,1,1,1,1,1,1,1,1,1,1,1,1,1,1,1,1,1,1,1,1,1,1,1,1,1,1,1,1,1,1,1,1,1,1,1,1,1
1,1,1,1,1,1,1,1,1,1,1,1,1,1,1,1,1,1,1,1,2,2,2,2,2,2,2,2,2,1,1,1,1,1,1,1,1,1,1,1,1,1,1,1,1,1,1,1,1,1
1,1,1,1,1,1,1,1,1,1,1,1,1,1,1,1,1,1,1,2,2,2,2,2,2,2,2,2,2,2,1,1,1,1,1,1,1,1,1,1,1,1,1,1,1,1,1,1,1,1
1,1,1,1,1,1,1,1,1,1,1,1,1,1,1,1,1,1,2,2,2,2,3,3,3,3,3,2,2,2,2,1,1,1,1,1,1,1,1,1,1,1,1,1,1,1,1,1,1,1
1,1,1,1,1,1,1,1,1,1,1,1,1,1,1,1,1,2,2,2,3,3,3,3,3,3,3,3,2,2,2,2,1,1,1,1,1,1,1,1,1,1,1,1,1,1,1,1,1,1
1,1,1,1,1,1,1,1,1,1,1,1,1,1,1,1,2,2,2,3,3,3,3,3,3,3,3,3,3,2,2,2,2,1,1,1,1,1,1,1,1,1,1,1,1,1,1,1,1,1
1,1,1,1,1,1,1,1,1,1,1,1,1,1,1,2,2,2,3,3,3,3,3,3,3,3,3,3,3,3,2,2,2,2,1,1,1,1,1,1,1,1,1,1,1,1,1,1,1,1
1,1,1,1,1,1,1,1,1,1,1,1,1,1,1,2,2,2,3,3,3,3,3,3,3,3,3,3,3,3,3,2,2,2,1,1,1,1,1,1,1,1,1,1,1,1,1,1,1,1
1,1,1,1,1,1,1,1,1,1,1,1,1,1,1,2,2,3,3,3,3,3,3,3,3,3,3,3,3,3,3,3,2,2,2,1,1,1,1,1,1,1,1,1,1,1,1,1,1,1
1,1,1,1,1,1,1,1,1,1,1,1,1,1,1,2,2,3,3,3,3,3,3,3,3,3,3,3,3,3,3,3,2,2,2,1,1,1,1,1,1,1,1,1,1,1,1,1,1,1
1,1,1,1,1,1,1,1,1,1,1,1,1,1,1,2,2,3,3,3,3,3,3,3,3,3,3,3,3,3,3,3,2,2,2,1,1,1,1,1,1,1,1,1,1,1,1,1,1,1
1,1,1,1,1,1,1,1,1,1,1,1,1,1,1,2,2,3,3,3,3,3,3,3,3,3,3,3,3,3,3,3,2,2,2,1,1,1,1,1,1,1,1,1,1,1,1,1,1,1
1,1,1,1,1,1,1,1,1,1,1,1,1,1,1,2,2,3,3,3,3,3,3,3,3,3,3,3,3,3,3,3,3,2,2,1,1,1,1,1,1,1,1,1,1,1,1,1,1,1
1,1,1,1,1,1,1,1,1,1,1,1,1,1,1,2,2,2,3,3,3,3,3,3,3,3,3,3,3,3,3,3,3,2,2,1,1,1,1,1,1,1,1,1,1,1,1,1,1,1
1,1,1,1,1,1,1,1,1,1,1,1,1,1,1,2,2,2,3,3,3,3,3,3,3,3,3,3,3,3,3,3,2,2,2,1,1,1,1,1,1,1,1,1,1,1,1,1,1,1
1,1,1,1,1,1,1,1,1,1,1,1,1,1,1,1,2,2,2,3,3,3,3,3,3,3,3,3,3,3,3,3,2,2,2,1,1,1,1,1,1,1,1,1,1,1,1,1,1,1
1,1,1,1,1,1,1,1,1,1,1,1,1,1,1,1,2,2,2,3,3,3,3,3,3,3,3,3,3,3,3,3,2,2,2,1,1,1,1,1,1,1,1,1,1,1,1,1,1,1
1,1,1,1,1,1,1,1,1,1,1,1,1,1,1,1,1,2,2,2,3,3,3,3,3,3,3,3,3,3,3,2,2,2,1,1,1,1,1,1,1,1,1,1,1,1,1,1,1,1
1,1,1,1,1,1,1,1,1,1,1,1,1,1,1,1,1,1,2,2,2,3,3,3,3,3,3,3,3,3,2,2,2,1,1,1,1,1,1,1,1,1,1,1,1,1,1,1,1,1
1,1,1,1,1,1,1,1,1,1,1,1,1,1,1,1,1,1,1,2,2,2,3,3,3,3,3,3,3,2,2,2,1,1,1,1,1,1,1,1,1,1,1,1,1,1,1,1,1,1
1,1,1,1,1,1,1,1,1,1,1,1,1,1,1,1,1,1,1,1,2,2,2,2,2,2,2,2,2,2,2,1,1,1,1,1,1,1,1,1,1,1,1,1,1,1,1,1,1,1
1,1,1,1,1,1,1,1,1,1,1,1,1,1,1,1,1,1,1,1,1,2,2,2,2,2,2,2,2,2,1,1,1,1,1,1,1,1,1,1,1,1,1,1,1,1,1,1,1,1
1,1,1,1,1,1,1,1,1,1,1,1,1,1,1,1,1,1,1,1,1,1,2,2,2,2,2,2,2,1,1,1,1,1,1,1,1,1,1,1,1,1,1,1,1,1,1,1,1,1
1,1,1,1,1,1,1,1,1,1,1,1,1,1,1,1,1,1,1,1,1,1,1,1,1,1,1,1,1,1,1,1,1,1,1,1,1,1,1,1,1,1,1,1,1,1,1,1,1,1
1,1,1,1,1,1,1,1,1,1,1,1,1,1,1,1,1,1,1,1,1,1,1,1,1,1,1,1,1,1,1,1,1,1,1,1,1,1,1,1,1,1,1,1,1,1,1,1,1,1
1,1,1,1,1,1,1,1,1,1,1,1,1,1,1,1,1,1,1,1,1,1,1,1,1,1,1,1,1,1,1,1,1,1,1,1,1,1,1,1,1,1,1,1,1,1,1,1,1,1
1,1,1,1,1,1,1,1,1,1,1,1,1,1,1,1,1,1,1,1,1,1,1,1,1,1,1,1,1,1,1,1,1,1,1,1,1,1,1,1,1,1,1,1,1,1,1,1,1,1
1,1,1,1,1,1,1,1,1,1,1,1,1,1,1,1,1,1,1,1,1,1,1,1,1,1,1,1,1,1,1,1,1,1,1,1,1,1,1,1,1,1,1,1,1,1,1,1,1,1
1,1,1,1,1,1,1,1,1,1,1,1,1,1,1,1,1,1,1,1,1,1,1,1,1,1,1,1,1,1,1,1,1,1,1,1,1,1,1,1,1,1,1,1,1,1,1,1,1,1
1,1,1,1,1,1,1,1,1,1,1,1,1,1,1,1,1,1,1,1,1,1,1,1,1,1,1,1,1,1,1,1,1,1,1,1,1,1,1,1,1,1,1,1,1,1,1,1,1,1
1,1,1,1,1,1,1,1,1,1,1,1,1,1,1,1,1,1,1,1,1,1,1,1,1,1,1,1,1,1,1,1,1,1,1,1,1,1,1,1,1,1,1,1,1,1,1,1,1,1
1,1,1,1,1,1,1,1,1,1,1,1,1,1,1,1,1,1,1,1,1,1,1,1,1,1,1,1,1,1,1,1,1,1,1,1,1,1,1,1,1,1,1,1,1,1,1,1,1,1
1,1,1,1,1,1,1,1,1,1,1,1,1,1,1,1,1,1,1,1,1,1,1,1,1,1,1,1,1,1,1,1,1,1,1,1,1,1,1,1,1,1,1,1,1,1,1,1,1,1
1,1,1,1,1,1,1,1,1,1,1,1,1,1,1,1,1,1,1,1,1,1,1,1,1,1,1,1,1,1,1,1,1,1,1,1,1,1,1,1,1,1,1,1,1,1,1,1,1,1
1,1,1,1,1,1,1,1,1,1,1,1,1,1,1,1,1,1,1,1,1,1,1,1,1,1,1,1,1,1,1,1,1,1,1,1,1,1,1,1,1,1,1,1,1,1,1,1,1,1
1,1,1,1,1,1,1,1,1,1,1,1,1,1,1,1,1,1,1,1,1,1,1,1,1,1,1,1,1,1,1,1,1,1,1,1,1,1,1,1,1,1,1,1,1,1,1,1,1,1
1,1,1,1,1,1,1,1,1,1,1,1,1,1,1,1,1,1,1,1,1,1,1,1,1,1,1,1,1,1,1,1,1,1,1,1,1,1,1,1,1,1,1,1,1,1,1,1,1,1
endlayer


layer
1,1,1,1,1,1,1,1,1,1,1,1,1,1,1,1,1,1,1,1,1,1,1,1,1,1,1,1,1,1,1,1,1,1,1,1,1,1,1,1,1,1,1,1,1,1,1,1,1,1
1,1,1,1,1,1,1,1,1,1,1,1,1,1,1,1,1,1,1,1,1,1,1,1,1,1,1,1,1,1,1,1,1,1,1,1,1,1,1,1,1,1,1,1,1,1,1,1,1,1
1,1,1,1,1,1,1,1,1,1,1,1,1,1,1,1,1,1,1,1,1,1,1,1,1,1,1,1,1,1,1,1,1,1,1,1,1,1,1,1,1,1,1,1,1,1,1,1,1,1
1,1,1,1,1,1,1,1,1,1,1,1,1,1,1,1,1,1,1,1,1,1,1,1,1,1,1,1,1,1,1,1,1,1,1,1,1,1,1,1,1,1,1,1,1,1,1,1,1,1
1,1,1,1,1,1,1,1,1,1,1,1,1,1,1,1,1,1,1,1,1,1,1,1,1,1,1,1,1,1,1,1,1,1,1,1,1,1,1,1,1,1,1,1,1,1,1,1,1,1
1,1,1,1,1,1,1,1,1,1,1,1,1,1,1,1,1,1,1,1,4,4,4,4,4,4,4,4,1,1,1,1,1,1,1,1,1,1,1,1,1,1,1,1,1,1,1,1,1,1
1,1,1,1,1,1,1,1,1,1,1,1,1,1,1,1,1,1,4,4,4,4,4,4,4,4,4,4,4,4,4,1,1,1,1,1,1,1,1,1,1,1,1,1,1,1,1,1,1,1
1,1,1,1,1,1,1,1,1,1,1,1,1,1,1,1,4,4,4,2,2,2,2,2,2,2,2,2,2,2,4,4,4,4,1,1,1,1,1,1,1,1,1,1,1,1,1,1,1,1
1,1,1,1,1,1,1,1,1,1,1,1,1,1,4,4,4,2,2,2,2,2,2,2,2,2,2,2,2,2,2,2,4,4,4,1,1,1,1,1,1,1,1,1,1,1,1,1,1,1
1,1,1,1,1,1,1,1,1,1,1,1,1,4,4,4,2,2,2,2,2,2,2,2,2,2,2,2,2,2,2,2,2,2,4,4,1,1,1,1,1,1,1,1,1,1,1,1,1,1
1,1,1,1,1,1,1,1,1,1,1,1,4,4,2,2,2,2,2,2,2,2,2,2,2,2,2,2,2,2,2,2,2,2,2,4,4,1,1,1,1,1,1,1,1,1,1,1,1,1
1,1,1,1,1,1,1,1,1,1,1,4,4,2,2,2,2,2,2,2,2,2,2,2,2,2,2,2,2,2,2,2,2,2,2,2,4,4,1,1,1,1,1,1,1,1,1,1,1,1
1,1,1,1,1,1,1,1,1,1,4,4,2,2,2,2,2,2,2,2,2,2,2,2,2,2,2,2,2,2,2,2,2,2,2,2,2,4,4,1,1,1,1,1,1,1,1,1,1,1
1,1,1,1,1,1,1,1,1,4,4,2,2,2,2,2,2,2,2,2,5,5,5,5,5,5,5,5,5,2,2,2,2,2,2,2,2,2,4,4,1,1,1,1,1,1,1,1,1,1
1,1,1,1,1,1,1,1,4,4,2,2,2,2,2,2,2,2,2,5,5,5,5,5,5,5,5,5,5,5,2,2,2,2,2,2,2,2,2,4,4,1,1,1,1,1,1,1,1,1
1,1,1,1,1,1,1,4,4,2,2,2,2,2,2,2,2,5,5,5,5,5,5,5,5,5,5,5,5,5,5,2,2,2,2,2,2,2,2,4,4,1,1,1,1,1,1,1,1,1
1,1,1,1,1,1,1,4,2,2,2,2,2,2,2,2,5,5,5,5,5,5,5,5,5,5,5,5,5,5,5,5,2,2,2,2,2,2,2,2,4,1,1,1,1,1,1,1,1,1
1,1,1,1,1,1,4,4,2,2,2,2,2,2,2,5,5,5,5,5,5,5,5,5,5,5,5,5,5,5,5,5,5,2,2,2,2,2,2,2,4,4,1,1,1,1,1,1,1,1
1,1,1,1,1,1,4,2,2,2,2,2,2,2,2,5,5,5,5,5,5,5,5,3,3,3,5,5,5,5,5,5,5,5,2,2,2,2,2,2,4,4,1,1,1,1,1,1,1,1
1,1,1,1,1,1,4,2,2,2,2,2,2,2,5,5,5,5,5,5,5,3,3,3,3,3,3,5,5,5,5,5,5,5,5,2,2,2,2,2,4,4,1,1,1,1,1,1,1,1
1,1,1,1,1,1,4,2,2,2,2,2,2,5,5,5,5,5,5,5,3,3,3,3,3,3,3,3,5,5,5,5,5,5,5,2,2,2,2,2,2,4,1,1,1,1,1,1,1,1
1,1,1,1,1,1,4,2,2,2,2,2,2,5,5,5,5,5,5,5,3,3,3,3,3,3,3,3,3,5,5,5,5,5,5,2,2,2,2,2,2,4,4,1,1,1,1,1,1,1
1,1,1,1,1,1,4,2,2,2,2,2,2,5,5,5,5,5,5,3,3,3,3,3,3,3,3,3,3,3,5,5,5,5,5,5,2,2,2,2,2,4,4,1,1,1,1,1,1,1
1,1,1,1,1,1,4,2,2,2,2,2,2,5,5,5,5,5,5,3,3,3,3,3,3,3,3,3,3,3,5,5,5,5,5,5,2,2,2,2,2,4,4,1,1,1,1,1,1,1
1,1,1,1,1,1,4,2,2,2,2,2,2,5,5,5,5,5,5,3,3,3,3,3,6,3,3,3,3,3,5,5,5,5,5,5,2,2,2,2,2,2,4,1,1,1,1,1,1,1
1,1,1,1,1,1,4,2,2,2,2,2,2,2,5,5,5,5,5,5,3,3,3,3,3,3,3,3,3,3,5,5,5,5,5,5,2,2,2,2,2,2,4,1,1,1,1,1,1,1
1,1,1,1,1,1,4,4,2,2,2,2,2,2,5,5,5,5,5,5,3,3,3,3,3,3,3,3,3,3,5,5,5,5,5,5,2,2,2,2,2,2,4,1,1,1,1,1,1,1
1,1,1,1,1,1,4,4,2,2,2,2,2,2,5,5,5,5,5,5,5,3,3,3,3,3,3,3,3,3,5,5,5,5,5,5,2,2,2,2,2,2,4,1,1,1,1,1,1,1
1,1,1,1,1,1,1,4,2,2,2,2,2,2,2,5,5,5,5,5,5,3,3,3,3,3,3,3,3,3,5,5,5,5,5,5,2,2,2,2,2,2,4,4,1,1,1,1,1,1
1,1,1,1,1,1,1,4,4,2,2,2,2,2,2,5,5,5,5,5,5,5,3,3,3,3,3,3,3,5,5,5,5,5,5,5,2,2,2,2,2,2,4,4,1,1,1,1,1,1
1,1,1,1,1,1,1,1,4,2,2,2,2,2,2,2,5,5,5,5,5,5,5,3,3,3,3,3,5,5,5,5,5,5,5,2,2,2,2,2,2,2,4,4,1,1,1,1,1,1
1,1,1,1,1,1,1,1,4,4,2,2,2,2,2,2,2,5,5,5,5,5,5,5,5,5,5,5,5,5,5,5,5,5,5,2,2,2,2,2,2,2,4,1,1,1,1,1,1,1
1,1,1,1,1,1,1,1,1,4,2,2,2,2,2,2,2,5,5,5,5,5,5,5,5,5,5,5,5,5,5,5,5,5,2,2,2,2,2,2,2,2,4,1,1,1,1,1,1,1
1,1,1,1,1,1,1,1,1,4,4,2,2,2,2,2,2,2,5,5,5,5,5,5,5,5,5,5,5,5,5,5,5,2,2,2,2,2,2,2,2,4,4,1,1,1,1,1,1,1
1,1,1,1,1,1,1,1,1,1,4,4,2,2,2,2,2,2,2,5,5,5,5,5,5,5,5,5,5,5,5,5,2,2,2,2,2,2,2,2,4,4,1,1,1,1,1,1,1,1
1,1,1,1,1,1,1,1,1,1,1,4,2,2,2,2,2,2,2,2,5,5,5,5,5,5,5,5,5,5,5,2,2,2,2,2,2,2,2,2,4,4,1,1,1,1,1,1,1,1
1,1,1,1,1,1,1,1,1,1,1,4,4,2,2,2,2,2,2,2,2,2,5,5,5,5,5,5,5,2,2,2,2,2,2,2,2,2,2,4,4,1,1,1,1,1,1,1,1,1
1,1,1,1,1,1,1,1,1,1,1,1,4,4,2,2,2,2,2,2,2,2,2,2,2,2,2,2,2,2,2,2,2,2,2,2,2,2,4,4,1,1,1,1,1,1,1,1,1,1
1,1,1,1,1,1,1,1,1,1,1,1,1,4,4,2,2,2,2,2,2,2,2,2,2,2,2,2,2,2,2,2,2,2,2,2,2,4,4,1,1,1,1,1,1,1,1,1,1,1
1,1,1,1,1,1,1,1,1,1,1,1,1,1,4,4,2,2,2,2,2,2,2,2,2,2,2,2,2,2,2,2,2,2,2,4,4,4,1,1,1,1,1,1,1,1,1,1,1,1
1,1,1,1,1,1,1,1,1,1,1,1,1,1,1,4,4,2,2,2,2,2,2,2,2,2,2,2,2,2,2,2,2,2,4,4,4,1,1,1,1,1,1,1,1,1,1,1,1,1
1,1,1,1,1,1,1,1,1,1,1,1,1,1,1,1,4,4,2,2,2,2,2,2,2,2,2,2,2,2,2,2,4,4,4,1,1,1,1,1,1,1,1,1,1,1,1,1,1,1
1,1,1,1,1,1,1,1,1,1,1,1,1,1,1,1,1,4,4,4,2,2,2,2,2,2,2,2,2,4,4,4,4,1,1,1,1,1,1,1,1,1,1,1,1,1,1,1,1,1
1,1,1,1,1,1,1,1,1,1,1,1,1,1,1,1,1,1,4,4,4,4,4,4,4,4,4,4,4,4,4,1,1,1,1,1,1,1,1,1,1,1,1,1,1,1,1,1,1,1
1,1,1,1,1,1,1,1,1,1,1,1,1,1,1,1,1,1,1,1,1,4,4,4,4,4,4,4,1,1,1,1,1,1,1,1,1,1,1,1,1,1,1,1,1,1,1,1,1,1
1,1,1,1,1,1,1,1,1,1,1,1,1,1,1,1,1,1,1,1,1,1,1,1,1,1,1,1,1,1,1,1,1,1,1,1,1,1,1,1,1,1,1,1,1,1,1,1,1,1
1,1,1,1,1,1,1,1,1,1,1,1,1,1,1,1,1,1,1,1,1,1,1,1,1,1,1,1,1,1,1,1,1,1,1,1,1,1,1,1,1,1,1,1,1,1,1,1,1,1
1,1,1,1,1,1,1,1,1,1,1,1,1,1,1,1,1,1,1,1,1,1,1,1,1,1,1,1,1,1,1,1,1,1,1,1,1,1,1,1,1,1,1,1,1,1,1,1,1,1
1,1,1,1,1,1,1,1,1,1,1,1,1,1,1,1,1,1,1,1,1,1,1,1,1,1,1,1,1,1,1,1,1,1,1,1,1,1,1,1,1,1,1,1,1,1,1,1,1,1
1,1,1,1,1,1,1,1,1,1,1,1,1,1,1,1,1,1,1,1,1,1,1,1,1,1,1,1,1,1,1,1,1,1,1,1,1,1,1,1,1,1,1,1,1,1,1,1,1,1
endlayer


layer
1,1,1,1,1,1,1,1,1,1,1,1,1,1,1,1,1,1,1,1,1,1,1,1,1,1,1,1,1,1,1,1,1,1,1,1,1,1,1,1,1,1,1,1,1,1,1,1,1,1
1,1,1,1,1,1,1,1,1,1,1,1,1,1,1,1,1,1,1,1,1,1,1,1,1,1,1,1,1,1,1,1,1,1,1,1,1,1,1,1,1,1,1,1,1,1,1,1,1,1
1,1,1,1,1,1,1,1,1,1,1,1,1,1,1,1,1,1,1,1,1,1,1,1,1,1,1,1,1,1,1,1,1,1,1,1,1,1,1,1,1,1,1,1,1,1,1,1,1,1
1,1,1,1,1,1,1,1,1,1,1,1,1,1,1,1,1,1,1,1,1,1,1,1,4,4,1,1,1,1,1,1,1,1,1,1,1,1,1,1,1,1,1,1,1,1,1,1,1,1
1,1,1,1,1,1,1,1,1,1,1,1,1,1,1,1,1,1,1,1,1,4,4,4,2,2,4,4,1,1,1,1,1,1,1,1,1,1,1,1,1,1,1,1,1,1,1,1,1,1
1,1,1,1,1,1,1,1,1,1,1,1,1,1,1,1,1,1,4,4,4,2,2,2,2,2,2,2,4,4,1,1,1,1,1,1,1,1,1,1,1,1,1,1,1,1,1,1,1,1
1,1,1,1,1,1,1,1,1,1,1,1,1,1,1,1,4,4,4,2,2,2,2,2,2,2,2,2,2,4,4,4,1,1,1,1,1,1,1,1,1,1,1,1,1,1,1,1,1,1
1,1,1,1,1,1,1,1,1,1,1,1,1,1,4,4,2,2,2,2,2,2,2,2,2,2,2,2,2,2,2,2,4,4,4,4,1,1,1,1,1,1,1,1,1,1,1,1,1,1
1,1,1,1,1,1,1,1,1,1,1,1,4,4,2,2,2,2,2,2,0,0,0,0,0,0,0,0,0,2,2,2,2,2,2,2,4,4,1,1,1,1,1,1,1,1,1,1,1,1
1,1,1,1,1,1,1,1,1,1,1,4,4,2,2,2,2,2,0,0,0,0,0,0,0,0,0,0,0,0,0,2,2,2,2,2,2,4,4,1,1,1,1,1,1,1,1,1,1,1
1,1,1,1,1,1,1,1,1,1,1,4,2,2,2,2,0,0,0,0,0,0,0,0,0,0,0,0,0,0,0,0,0,2,2,2,2,2,2,4,1,1,1,1,1,1,1,1,1,1
1,1,1,1,1,1,1,1,1,4,4,2,2,2,2,0,0,0,0,0,0,0,0,0,0,0,0,0,0,0,0,0,0,0,0,2,2,2,2,2,4,1,1,1,1,1,1,1,1,1
1,1,1,1,1,1,1,1,4,4,2,2,2,0,0,0,0,0,0,0,0,0,0,0,0,0,0,0,0,0,0,0,0,0,0,0,2,2,2,2,2,4,1,1,1,1,1,1,1,1
1,1,1,1,1,1,4,4,2,2,2,2,0,0,0,0,0,0,0,0,0,0,0,0,0,0,0,0,0,0,0,0,0,0,0,0,0,2,2,2,2,4,1,1,1,1,1,1,1,1
1,1,1,1,1,4,4,2,2,2,2,0,0,0,0,0,0,0,0,0,0,0,0,0,0,0,0,0,0,0,0,0,0,0,0,0,0,0,2,2,4,1,1,1,1,1,1,1,1,1
1,1,1,1,1,4,2,2,2,2,0,0,0,0,0,0,0,0,0,0,0,0,0,0,0,0,0,0,0,0,0,0,0,0,0,0,0,0,2,2,4,1,1,1,1,1,1,1,1,1
1,1,1,1,1,4,2,2,2,2,0,0,0,0,0,0,0,0,0,0,0,0,0,0,0,0,0,0,0,0,0,0,0,0,0,0,0,0,0,2,2,4,1,1,1,1,1,1,1,1
1,1,1,1,1,4,2,2,2,0,0,0,0,0,0,0,0,0,0,0,0,0,0,0,0,0,0,0,0,0,0,0,0,0,0,0,0,0,0,2,2,2,4,1,1,1,1,1,1,1
1,1,1,1,1,4,2,2,2,0,0,0,0,0,0,0,0,0,0,0,0,0,0,0,0,0,0,0,0,0,0,0,0,0,0,0,0,0,0,2,2,2,4,1,1,1,1,1,1,1
1,1,1,1,1,4,2,2,0,0,0,0,0,0,0,0,0,0,0,0,0,0,0,0,0,0,0,0,0,0,0,0,0,0,0,0,0,0,0,2,2,2,4,1,1,1,1,1,1,1
1,1,1,1,1,4,2,2,0,0,0,0,0,0,0,0,0,0,0,0,0,0,0,0,0,0,0,0,0,0,0,0,0,0,0,0,0,0,0,0,2,2,4,1,1,1,1,1,1,1
1,1,1,1,1,4,2,2,0,0,0,0,0,0,0,0,0,0,0,0,0,0,0,0,0,0,0,0,0,0,0,0,0,0,0,0,0,0,0,0,2,2,4,1,1,1,1,1,1,1
1,1,1,1,1,4,2,2,0,0,0,0,0,0,0,0,0,0,0,0,0,0,0,2,2,2,0,0,0,0,0,0,0,0,0,0,0,0,0,0,2,2,4,1,1,1,1,1,1,1
1,1,1,1,1,4,2,2,0,0,0,0,0,0,0,0,0,0,0,0,0,0,0,2,7,2,2,0,0,0,0,0,0,0,0,0,0,0,0,0,2,2,2,4,1,1,1,1,1,1
1,1,1,1,1,4,2,2,0,0,0,0,0,0,0,0,0,0,0,0,0,0,2,7,8,7,2,0,0,0,0,0,0,0,0,0,0,0,0,0,0,2,2,4,1,1,1,1,1,1
1,1,1,1,1,4,2,2,2,0,0,0,0,0,0,0,0,0,0,0,0,0,0,2,7,2,2,0,0,0,0,0,0,0,0,0,0,0,0,0,0,2,2,2,4,1,1,1,1,1
1,1,1,1,1,4,2,2,2,0,0,0,0,0,0,0,0,0,0,0,0,0,0,0,2,2,2,0,0,0,0,0,0,0,0,0,0,0,0,0,0,2,2,2,4,1,1,1,1,1
1,1,1,1,1,4,2,2,2,0,0,0,0,0,0,0,0,0,0,0,0,0,0,0,0,0,0,0,0,0,0,0,0,0,0,0,0,0,0,0,0,2,2,2,4,1,1,1,1,1
1,1,1,1,1,4,2,2,2,2,0,0,0,0,0,0,0,0,0,0,0,0,0,0,0,0,0,0,0,0,0,0,0,0,0,0,0,0,0,0,0,2,2,2,4,1,1,1,1,1
1,1,1,1,1,4,4,2,2,2,0,0,0,0,0,0,0,0,0,0,0,0,0,0,0,0,0,0,0,0,0,0,0,0,0,0,0,0,0,0,0,2,2,4,1,1,1,1,1,1
1,1,1,1,1,1,4,4,2,2,2,0,0,0,0,0,0,0,0,0,0,0,0,0,0,0,0,0,0,0,0,0,0,0,0,0,0,0,0,0,0,2,2,4,1,1,1,1,1,1
1,1,1,1,1,1,1,4,4,2,2,0,0,0,0,0,0,0,0,0,0,0,0,0,0,0,0,0,0,0,0,0,0,0,0,0,0,0,0,0,0,2,2,4,1,1,1,1,1,1
1,1,1,1,1,1,1,1,4,4,2,2,0,0,0,0,0,0,0,0,0,0,0,0,0,0,0,0,0,0,0,0,0,0,0,0,0,0,0,0,2,2,2,4,1,1,1,1,1,1
1,1,1,1,1,1,1,1,1,4,2,2,0,0,0,0,0,0,0,0,0,0,0,0,0,0,0,0,0,0,0,0,0,0,0,0,0,0,0,0,2,2,2,4,1,1,1,1,1,1
1,1,1,1,1,1,1,1,1,1,4,2,2,0,0,0,0,0,0,0,0,0,0,0,0,0,0,0,0,0,0,0,0,0,0,0,0,0,0,2,2,2,2,4,1,1,1,1,1,1
1,1,1,1,1,1,1,1,1,1,4,2,2,2,0,0,0,0,0,0,0,0,0,0,0,0,0,0,0,0,0,0,0,0,0,0,0,0,2,2,2,2,4,4,1,1,1,1,1,1
1,1,1,1,1,1,1,1,1,1,4,4,2,2,0,0,0,0,0,0,0,0,0,0,0,0,0,0,0,0,0,0,0,0,0,0,0,2,2,2,2,2,4,1,1,1,1,1,1,1
1,1,1,1,1,1,1,1,1,1,1,4,2,2,2,0,0,0,0,0,0,0,0,0,0,0,0,0,0,0,0,0,0,0,0,0,2,2,2,2,2,4,1,1,1,1,1,1,1,1
1,1,1,1,1,1,1,1,1,1,1,4,4,2,2,2,0,0,0,0,0,0,0,0,0,0,0,0,0,0,0,0,0,0,0,2,2,2,2,2,4,1,1,1,1,1,1,1,1,1
1,1,1,1,1,1,1,1,1,1,1,1,4,2,2,2,2,0,0,0,0,0,0,0,0,0,0,0,0,0,0,0,0,2,2,2,2,2,4,4,1,1,1,1,1,1,1,1,1,1
1,1,1,1,1,1,1,1,1,1,1,1,1,4,2,2,2,2,2,0,0,0,0,0,0,0,0,0,0,0,0,2,2,2,2,2,4,4,1,1,1,1,1,1,1,1,1,1,1,1
1,1,1,1,1,1,1,1,1,1,1,1,1,4,4,2,2,2,2,2,0,0,0,0,0,0,0,0,0,2,2,2,2,2,4,4,1,1,1,1,1,1,1,1,1,1,1,1,1,1
1,1,1,1,1,1,1,1,1,1,1,1,1,1,4,4,2,2,2,2,2,2,2,2,2,2,2,2,2,2,2,2,4,4,1,1,1,1,1,1,1,1,1,1,1,1,1,1,1,1
1,1,1,1,1,1,1,1,1,1,1,1,1,1,1,4,4,4,2,2,2,2,2,2,2,2,2,2,2,2,2,4,1,1,1,1,1,1,1,1,1,1,1,1,1,1,1,1,1,1
1,1,1,1,1,1,1,1,1,1,1,1,1,1,1,1,1,1,4,4,4,4,4,2,2,2,2,2,4,4,4,1,1,1,1,1,1,1,1,1,1,1,1,1,1,1,1,1,1,1
1,1,1,1,1,1,1,1,1,1,1,1,1,1,1,1,1,1,1,1,1,1,4,4,4,4,4,4,1,1,1,1,1,1,1,1,1,1,1,1,1,1,1,1,1,1,1,1,1,1
1,1,1,1,1,1,1,1,1,1,1,1,1,1,1,1,1,1,1,1,1,1,1,1,1,1,1,1,1,1,1,1,1,1,1,1,1,1,1,1,1,1,1,1,1,1,1,1,1,1
1,1,1,1,1,1,1,1,1,1,1,1,1,1,1,1,1,1,1,1,1,1,1,1,1,1,1,1,1,1,1,1,1,1,1,1,1,1,1,1,1,1,1,1,1,1,1,1,1,1
1,1,1,1,1,1,1,1,1,1,1,1,1,1,1,1,1,1,1,1,1,1,1,1,1,1,1,1,1,1,1,1,1,1,1,1,1,1,1,1,1,1,1,1,1,1,1,1,1,1
1,1,1,1,1,1,1,1,1,1,1,1,1,1,1,1,1,1,1,1,1,1,1,1,1,1,1,1,1,1,1,1,1,1,1,1,1,1,1,1,1,1,1,1,1,1,1,1,1,1
endlayer


layer
1,1,1,1,1,1,1,1,1,1,1,1,1,1,1,1,9,1,1,1,1,9,9,1,1,1,9,1,1,1,1,1,1,1,1,1,1,1,1,1,1,1,1,1,1,1,1,1,1,1
1,1,1,1,1,1,1,1,1,1,1,1,1,1,1,9,9,9,9,9,9,9,9,9,9,9,9,9,1,1,9,9,9,1,1,1,1,1,1,9,1,1,1,1,1,1,1,1,1,1
1,1,1,1,1,1,1,1,1,1,1,1,1,1,1,9,4,4,9,9,9,4,4,9,9,9,9,9,1,1,1,9,1,1,1,1,1,1,1,9,9,1,1,1,1,1,1,1,1,1
1,1,1,1,9,9,9,1,1,1,1,1,1,1,9,9,4,4,4,9,9,9,9,4,4,2,9,9,1,1,9,9,1,1,1,9,9,9,9,9,9,1,1,1,1,1,1,1,1,1
1,1,1,1,1,9,9,9,9,9,9,1,1,1,9,9,4,4,9,9,9,2,2,2,2,2,2,2,9,9,9,9,9,9,9,9,4,4,4,9,9,1,1,1,1,1,1,1,1,1
1,1,1,1,1,1,9,9,4,9,9,9,1,1,9,9,4,9,9,2,2,2,2,0,0,0,0,2,2,9,9,9,9,9,9,4,4,4,9,9,1,1,1,1,1,1,1,1,1,1
1,1,1,1,1,1,1,9,4,4,4,9,1,1,9,9,2,2,2,2,0,0,0,0,0,0,0,0,2,2,2,2,9,4,4,4,4,4,9,1,1,1,1,1,1,1,9,1,1,1
1,1,1,1,1,1,1,9,9,4,4,9,9,9,2,2,2,2,2,0,0,0,0,0,0,0,0,0,0,0,2,2,2,2,2,4,4,9,9,1,1,1,1,1,9,9,1,1,1,1
1,1,1,1,1,1,1,1,9,9,4,9,9,2,2,2,0,0,0,0,0,0,0,0,0,0,0,0,0,0,0,0,0,0,2,2,2,9,9,1,1,1,9,9,9,9,1,1,1,1
1,1,1,9,9,1,1,1,1,9,9,9,2,2,0,0,0,0,0,0,0,0,0,0,0,0,0,0,0,0,0,0,0,0,0,0,2,2,2,9,9,9,9,9,9,1,1,1,1,1
1,1,1,1,9,1,1,1,1,9,4,2,2,0,0,0,0,0,0,0,0,0,0,0,0,0,0,0,0,0,0,0,0,0,0,0,0,0,2,2,9,4,4,4,9,1,1,1,1,1
1,1,1,1,1,9,9,9,9,9,2,2,0,0,0,0,0,0,0,0,0,0,0,0,0,0,0,0,0,0,0,0,0,0,0,0,0,0,0,2,2,9,4,4,9,9,1,1,1,1
1,1,1,1,1,9,9,4,4,2,2,0,0,0,0,0,0,0,0,0,0,0,0,0,0,0,0,0,0,0,0,0,0,0,0,0,0,0,0,0,2,2,9,4,9,9,1,1,1,1
1,9,9,9,9,9,4,2,2,0,0,0,0,0,0,0,0,0,0,0,0,0,0,0,0,0,0,0,0,0,0,0,0,0,0,0,0,0,0,0,2,2,9,4,9,9,1,1,1,1
1,1,9,9,9,9,2,2,0,0,0,0,0,0,0,0,0,0,0,0,0,0,0,0,0,0,0,0,0,0,0,0,0,0,0,0,0,0,0,0,2,9,9,4,4,9,1,1,1,1
1,9,9,9,9,2,2,0,0,0,0,0,0,0,0,0,0,0,0,0,0,0,0,0,0,0,0,0,0,0,0,0,0,0,0,0,0,0,0,0,2,9,4,4,4,9,1,1,1,1
1,1,1,1,9,2,2,0,0,0,0,0,0,0,0,0,0,0,0,0,0,0,0,0,0,0,0,0,0,0,0,0,0,0,0,0,0,0,0,0,2,2,9,4,4,9,9,1,1,1
1,1,1,1,9,2,0,0,0,0,0,0,0,0,0,0,0,0,0,0,0,0,0,0,0,0,0,0,0,0,0,0,0,0,0,0,0,0,0,0,0,2,2,9,4,9,9,9,1,1
1,1,9,1,9,2,0,0,0,0,0,0,0,0,0,0,0,0,0,0,0,0,0,0,0,0,0,0,0,0,0,0,0,0,0,0,0,0,0,0,0,2,2,9,9,4,9,1,1,1
9,9,9,9,9,2,0,0,0,0,0,0,0,0,0,0,0,0,0,0,0,0,0,0,0,0,0,0,0,0,0,0,0,0,0,0,0,0,0,0,0,0,2,9,9,9,9,1,1,1
9,9,4,9,9,2,0,0,0,0,0,0,0,0,0,0,0,0,0,0,0,0,0,0,0,0,0,0,0,0,0,0,0,0,0,0,0,0,0,0,0,0,2,9,9,9,9,1,1,1
9,9,9,4,9,2,0,0,0,0,0,0,0,0,0,0,0,0,0,0,0,0,0,0,0,0,0,0,0,0,0,0,0,0,0,0,0,0,0,0,0,2,2,9,4,4,9,9,1,1
1,9,9,9,4,2,2,0,0,0,0,0,0,0,0,0,0,0,0,0,0,0,0,0,0,0,0,0,0,0,0,0,0,0,0,0,0,0,0,0,0,2,2,9,4,4,4,9,9,1
1,1,1,9,4,2,2,0,0,0,0,0,0,0,0,0,0,0,0,0,0,0,0,0,0,0,0,0,0,0,0,0,0,0,0,0,0,0,0,0,0,0,2,2,9,4,4,9,9,1
1,1,9,9,4,2,2,0,0,0,0,0,0,0,0,0,0,0,0,0,0,0,0,0,7,0,0,0,0,0,0,0,0,0,0,0,0,0,0,0,0,0,2,2,9,4,4,9,1,1
1,1,9,9,4,2,2,0,0,0,0,0,0,0,0,0,0,0,0,0,0,0,0,0,0,0,0,0,0,0,0,0,0,0,0,0,0,0,0,0,0,0,0,2,2,4,4,9,9,1
1,1,1,9,9,2,0,0,0,0,0,0,0,0,0,0,0,0,0,0,0,0,0,0,0,0,0,0,0,0,0,0,0,0,0,0,0,0,0,0,0,0,0,2,2,9,4,9,9,1
1,1,9,9,9,2,0,0,0,0,0,0,0,0,0,0,0,0,0,0,0,0,0,0,0,0,0,0,0,0,0,0,0,0,0,0,0,0,0,0,0,0,0,2,2,9,9,9,1,1
9,9,9,4,9,2,2,0,0,0,0,0,0,0,0,0,0,0,0,0,0,0,0,0,0,0,0,0,0,0,0,0,0,0,0,0,0,0,0,0,0,0,0,2,2,9,1,1,1,1
1,1,9,9,9,9,2,0,0,0,0,0,0,0,0,0,0,0,0,0,0,0,0,0,0,0,0,0,0,0,0,0,0,0,0,0,0,0,0,0,0,0,0,2,9,1,1,1,1,1
1,1,1,9,9,9,2,2,2,0,0,0,0,0,0,0,0,0,0,0,0,0,0,0,0,0,0,0,0,0,0,0,0,0,0,0,0,0,0,0,0,0,2,2,9,1,9,9,1,1
1,1,1,9,9,4,9,9,2,2,0,0,0,0,0,0,0,0,0,0,0,0,0,0,0,0,0,0,0,0,0,0,0,0,0,0,0,0,0,0,0,0,2,2,9,9,9,9,9,1
1,9,9,9,9,9,4,4,9,2,0,0,0,0,0,0,0,0,0,0,0,0,0,0,0,0,0,0,0,0,0,0,0,0,0,0,0,0,0,0,0,0,0,2,9,4,9,9,9,1
1,1,1,1,1,9,9,4,4,2,2,0,0,0,0,0,0,0,0,0,0,0,0,0,0,0,0,0,0,0,0,0,0,0,0,0,0,0,0,0,0,0,0,2,9,9,9,1,1,1
1,1,1,1,1,1,9,4,4,9,2,0,0,0,0,0,0,0,0,0,0,0,0,0,0,0,0,0,0,0,0,0,0,0,0,0,0,0,0,0,0,0,2,2,9,9,9,1,1,1
1,1,1,1,1,1,9,9,9,9,2,2,0,0,0,0,0,0,0,0,0,0,0,0,0,0,0,0,0,0,0,0,0,0,0,0,0,0,0,0,0,0,2,9,9,9,9,9,1,1
1,1,1,1,1,1,9,9,9,9,9,2,0,0,0,0,0,0,0,0,0,0,0,0,0,0,0,0,0,0,0,0,0,0,0,0,0,0,0,0,0,2,2,4,9,9,1,9,9,1
1,1,1,1,9,9,1,1,1,1,9,2,2,0,0,0,0,0,0,0,0,0,0,0,0,0,0,0,0,0,0,0,0,0,0,0,0,0,0,0,2,2,9,9,9,1,1,1,1,1
1,1,1,1,1,1,1,1,1,1,9,9,2,0,0,0,0,0,0,0,0,0,0,0,0,0,0,0,0,0,0,0,0,0,0,0,0,0,2,2,2,9,1,9,9,1,1,1,1,1
1,1,1,1,1,1,1,1,1,9,9,9,2,2,0,0,0,0,0,0,0,0,0,0,0,0,0,0,0,0,0,0,0,0,0,0,0,2,2,2,9,1,1,1,1,1,1,1,1,1
1,1,1,1,1,1,1,1,9,9,9,9,9,2,2,0,0,0,0,0,0,0,0,0,0,0,0,0,0,0,0,0,0,0,2,2,2,2,9,9,9,9,1,1,1,1,1,1,1,1
1,1,1,1,1,1,9,9,9,9,9,9,9,9,2,2,0,0,0,0,0,0,0,0,0,0,0,0,0,0,0,0,2,2,2,2,9,9,4,9,9,9,1,1,1,1,1,1,1,1
1,1,1,1,9,1,1,1,9,9,1,1,9,9,4,2,2,0,0,0,0,0,0,0,0,0,0,0,0,0,0,2,2,2,4,4,4,4,9,9,9,9,9,1,1,1,1,1,1,1
1,1,1,1,1,1,1,9,9,1,1,1,9,9,4,4,2,2,2,2,2,0,0,0,0,0,0,0,0,2,2,4,4,4,4,4,4,9,9,1,1,9,9,1,1,1,1,1,1,1
1,1,1,1,1,9,1,1,1,1,1,1,1,9,4,9,9,9,2,2,2,2,2,2,2,2,2,2,4,4,4,4,4,4,4,9,9,9,9,1,1,1,9,9,1,1,1,1,1,1
1,1,1,1,1,1,1,1,1,1,1,1,9,9,9,9,9,9,9,4,4,9,9,2,2,2,2,4,4,4,4,4,4,4,9,9,9,9,9,1,1,1,1,9,9,1,1,1,1,1
1,1,1,1,1,1,1,1,1,1,1,9,9,9,1,1,1,1,9,9,4,4,9,9,9,9,9,4,4,4,4,4,9,9,9,1,1,1,9,1,1,1,1,1,1,1,1,1,1,1
1,1,1,1,1,1,1,1,1,1,1,1,9,1,1,1,1,1,9,9,9,9,9,9,9,1,9,9,9,9,9,4,9,1,1,1,1,1,1,1,1,1,1,1,1,1,1,1,1,1
1,1,1,1,1,1,1,1,1,1,1,1,1,1,1,1,1,1,9,9,1,1,9,9,1,1,9,9,9,9,9,9,9,1,1,1,1,1,1,1,1,1,1,1,1,1,1,1,1,1
1,1,1,1,1,1,1,1,1,1,1,1,1,1,1,1,1,1,1,1,1,1,9,1,1,1,1,1,1,1,1,1,1,1,1,1,1,1,1,1,1,1,1,1,1,1,1,1,1,1
endlayer


layer
1,1,1,1,1,1,1,1,1,1,1,1,1,1,1,1,9,1,1,1,1,9,9,1,1,1,9,1,1,1,1,1,1,1,1,1,1,1,1,1,1,1,1,1,1,1,1,1,1,1
1,1,1,1,1,1,1,1,1,1,1,1,1,1,1,9,9,9,9,9,9,9,9,9,9,9,9,9,1,1,2,9,9,1,1,1,1,1,1,9,1,1,1,1,1,1,1,1,1,1
1,1,1,1,1,1,1,1,1,1,1,1,1,1,1,9,9,9,9,9,9,2,2,9,9,9,9,2,1,1,1,9,1,1,1,1,1,1,1,9,9,1,1,1,1,1,1,1,1,1
1,1,1,1,9,9,9,1,1,1,1,1,1,1,2,9,9,2,9,9,9,2,2,2,2,9,9,2,1,1,2,9,1,1,1,9,9,9,9,9,9,1,1,1,1,1,1,1,1,1
1,1,1,1,1,9,9,9,9,9,2,1,1,1,2,9,9,2,2,2,2,0,2,2,2,2,2,0,0,0,2,9,9,9,9,9,9,9,9,9,9,1,1,1,1,1,1,1,1,1
1,1,1,1,1,1,9,9,9,9,9,2,1,1,2,9,9,2,2,0,0,0,0,0,0,0,0,0,0,0,2,9,9,9,9,9,2,9,9,9,1,1,1,1,1,1,1,1,1,1
1,1,1,1,1,1,1,9,9,9,9,2,1,1,0,2,2,2,0,0,0,0,0,0,0,0,0,0,0,0,0,2,2,2,2,2,2,9,9,1,1,1,1,1,1,1,9,1,1,1
1,1,1,1,1,1,1,9,9,9,9,2,0,0,0,0,2,0,0,0,0,0,0,0,0,0,0,0,0,0,0,0,2,2,2,2,2,9,9,1,1,1,1,1,9,9,1,1,1,1
1,1,1,1,1,1,1,1,9,9,9,9,2,0,0,0,0,0,0,0,0,0,0,0,0,0,0,0,0,0,0,0,0,0,2,2,2,9,9,1,1,1,9,9,9,9,1,1,1,1
1,1,1,9,9,1,1,1,1,9,9,9,2,0,0,0,0,0,0,0,0,0,0,0,0,0,0,0,0,0,0,0,0,0,0,2,2,2,9,9,9,9,9,9,9,1,1,1,1,1
1,1,1,1,9,1,1,1,1,9,9,2,0,0,0,0,0,0,0,0,0,0,0,0,0,0,0,0,0,0,0,0,0,0,0,0,0,0,2,2,9,2,2,9,9,1,1,1,1,1
1,1,1,1,1,9,9,9,9,9,9,2,0,0,0,0,0,0,0,0,0,0,0,0,0,0,0,0,0,0,0,0,0,0,0,0,0,0,0,2,2,2,9,9,9,9,1,1,1,1
1,1,1,1,1,9,9,9,9,2,2,0,0,0,0,0,0,0,0,0,0,0,0,0,0,0,0,0,0,0,0,0,0,0,0,0,0,0,0,0,2,2,2,2,2,9,1,1,1,1
1,9,9,9,9,9,9,2,2,2,0,0,0,0,0,0,0,0,0,0,0,0,0,0,0,0,0,0,0,0,0,0,0,0,0,0,0,0,0,0,0,0,2,2,2,9,1,1,1,1
1,1,9,9,9,2,2,2,0,0,0,0,0,0,0,0,0,0,0,0,0,0,0,0,0,0,0,0,0,0,0,0,0,0,0,0,0,0,0,0,0,2,2,9,9,9,1,1,1,1
1,2,2,2,2,0,0,0,0,0,0,0,0,0,0,0,0,0,0,0,0,0,0,0,0,0,0,0,0,0,0,0,0,0,0,0,0,0,0,2,2,2,9,9,9,9,1,1,1,1
1,1,1,1,0,0,0,0,0,0,0,0,0,0,0,0,0,0,0,0,0,0,0,0,0,0,0,0,0,0,0,0,0,0,0,0,0,0,0,0,2,2,9,9,9,9,9,1,1,1
1,1,1,1,0,0,0,0,0,0,0,0,0,0,0,0,0,0,0,0,0,0,0,0,0,0,0,0,0,0,0,0,0,0,0,0,0,0,0,0,0,2,2,9,9,9,9,9,1,1
1,1,2,1,0,0,0,0,0,0,0,0,0,0,0,0,0,0,0,0,0,0,0,0,0,0,0,0,0,0,0,0,0,0,0,0,0,0,0,0,0,0,0,2,2,2,9,1,1,1
9,9,9,2,2,0,0,0,0,0,0,0,0,0,0,0,0,0,0,0,0,0,0,0,0,0,0,0,0,0,0,0,0,0,0,0,0,0,0,0,0,0,0,2,2,9,9,1,1,1
9,9,9,9,2,0,0,0,0,0,0,0,0,0,0,0,0,0,0,0,0,0,0,0,0,0,0,0,0,0,0,0,0,0,0,0,0,0,0,0,0,0,0,2,2,9,9,1,1,1
9,9,9,9,9,2,0,0,0,0,0,0,0,0,0,0,0,0,0,0,0,0,0,0,0,0,0,0,0,0,0,0,0,0,0,0,0,0,0,0,0,0,0,2,9,9,9,9,1,1
1,9,9,9,9,2,2,0,0,0,0,0,0,0,0,0,0,0,0,0,0,0,0,0,0,0,0,0,0,0,0,0,0,0,0,0,0,0,0,0,0,2,2,2,9,9,9,9,9,1
1,1,1,9,9,9,0,0,0,0,0,0,0,0,0,0,0,0,0,0,0,0,0,0,0,0,0,0,0,0,0,0,0,0,0,0,0,0,0,0,2,2,2,2,2,2,9,9,9,1
1,1,9,9,9,9,0,0,0,0,0,0,0,0,0,0,0,0,0,0,0,0,0,0,0,0,0,0,0,0,0,0,0,0,0,0,0,0,0,0,0,0,0,0,2,9,9,9,1,1
1,1,9,9,9,2,0,0,0,0,0,0,0,0,0,0,0,0,0,0,0,0,0,0,0,0,0,0,0,0,0,0,0,0,0,0,0,0,0,0,0,0,0,0,2,9,9,9,9,1
1,1,1,9,9,2,0,0,0,0,0,0,0,0,0,0,0,0,0,0,0,0,0,0,0,0,0,0,0,0,0,0,0,0,0,0,0,0,0,0,0,0,0,0,2,9,9,9,9,1
1,1,9,9,9,0,0,0,0,0,0,0,0,0,0,0,0,0,0,0,0,0,0,0,0,0,0,0,0,0,0,0,0,0,0,0,0,0,0,0,0,0,0,0,0,2,9,9,1,1
9,9,9,9,9,2,0,0,0,0,0,0,0,0,0,0,0,0,0,0,0,0,0,0,0,0,0,0,0,0,0,0,0,0,0,0,0,0,0,0,0,0,0,0,0,0,1,1,1,1
1,1,9,9,9,2,0,0,0,0,0,0,0,0,0,0,0,0,0,0,0,0,0,0,0,0,0,0,0,0,0,0,0,0,0,0,0,0,0,0,0,0,0,0,0,1,1,1,1,1
1,1,1,9,9,9,2,0,0,0,0,0,0,0,0,0,0,0,0,0,0,0,0,0,0,0,0,0,0,0,0,0,0,0,0,0,0,0,0,0,0,0,0,0,0,1,2,2,1,1
1,1,1,9,9,9,9,2,2,0,0,0,0,0,0,0,0,0,0,0,0,0,0,0,0,0,0,0,0,0,0,0,0,0,0,0,0,0,0,0,0,0,0,0,2,2,2,9,9,1
1,9,9,9,9,9,9,9,2,2,0,0,0,0,0,0,0,0,0,0,0,0,0,0,0,0,0,0,0,0,0,0,0,0,0,0,0,0,0,0,0,0,0,0,2,9,9,9,9,1
1,1,1,1,1,9,9,9,9,2,2,0,0,0,0,0,0,0,0,0,0,0,0,0,0,0,0,0,0,0,0,0,0,0,0,0,0,0,0,0,0,0,0,0,2,2,9,1,1,1
1,1,1,1,1,1,9,9,9,2,2,0,0,0,0,0,0,0,0,0,0,0,0,0,0,0,0,0,0,0,0,0,0,0,0,0,0,0,0,0,0,2,0,0,2,2,9,1,1,1
1,1,1,1,1,1,9,9,9,2,0,0,0,0,0,0,0,0,0,0,0,0,0,0,0,0,0,0,0,0,0,0,0,0,0,0,0,0,0,0,0,2,2,2,9,9,9,9,1,1
1,1,1,1,1,1,9,9,2,0,0,0,0,0,0,0,0,0,0,0,0,0,0,0,0,0,0,0,0,0,0,0,0,0,0,0,0,0,0,0,0,2,2,9,9,9,1,9,9,1
1,1,1,1,9,9,1,1,1,1,0,0,2,0,0,0,0,0,0,0,0,0,0,0,0,0,0,0,0,0,0,0,0,0,0,0,0,0,0,0,0,0,2,9,9,1,1,1,1,1
1,1,1,1,1,1,1,1,1,1,0,2,2,0,0,0,0,0,0,0,0,0,0,0,0,0,0,0,0,0,0,0,0,0,0,0,0,0,0,0,0,0,1,9,9,1,1,1,1,1
1,1,1,1,1,1,1,1,1,2,2,2,2,0,0,0,0,0,0,0,0,0,0,0,0,0,0,0,0,0,0,0,0,0,0,0,0,0,2,2,0,1,1,1,1,1,1,1,1,1
1,1,1,1,1,1,1,1,9,9,9,9,2,2,0,0,0,0,0,0,0,0,0,0,0,0,0,0,0,0,0,0,0,0,0,2,2,2,2,2,2,2,1,1,1,1,1,1,1,1
1,1,1,1,1,1,9,9,9,9,9,9,9,2,2,2,0,0,0,0,0,0,0,0,0,0,0,0,0,0,0,0,2,2,2,9,9,9,9,9,9,9,1,1,1,1,1,1,1,1
1,1,1,1,9,1,1,1,9,9,1,1,9,9,2,2,2,0,0,0,0,0,0,0,0,0,0,0,0,0,2,2,2,2,9,9,2,9,9,9,9,9,9,1,1,1,1,1,1,1
1,1,1,1,1,1,1,9,9,1,1,1,9,9,2,2,2,2,2,2,2,0,0,0,0,0,2,2,2,2,2,2,9,9,9,2,2,9,9,1,1,9,9,1,1,1,1,1,1,1
1,1,1,1,1,9,1,1,1,1,1,1,1,9,2,9,9,9,9,2,2,2,0,0,0,2,2,9,9,9,9,9,9,9,9,9,2,2,9,1,1,1,9,9,1,1,1,1,1,1
1,1,1,1,1,1,1,1,1,1,1,1,9,9,9,9,9,9,9,9,2,2,2,0,0,2,9,9,9,2,9,9,9,9,9,9,9,9,9,1,1,1,1,9,9,1,1,1,1,1
1,1,1,1,1,1,1,1,1,1,1,9,9,9,1,1,1,1,9,9,9,2,2,2,0,0,9,9,2,2,2,9,9,9,9,1,1,1,9,1,1,1,1,1,1,1,1,1,1,1
1,1,1,1,1,1,1,1,1,1,1,1,9,1,1,1,1,1,9,9,9,9,9,9,9,1,9,9,9,9,9,9,9,1,1,1,1,1,1,1,1,1,1,1,1,1,1,1,1,1
1,1,1,1,1,1,1,1,1,1,1,1,1,1,1,1,1,1,9,9,1,1,9,9,1,1,9,9,9,9,9,9,9,1,1,1,1,1,1,1,1,1,1,1,1,1,1,1,1,1
1,1,1,1,1,1,1,1,1,1,1,1,1,1,1,1,1,1,1,1,1,1,9,1,1,1,1,1,1,1,1,1,1,1,1,1,1,1,1,1,1,1,1,1,1,1,1,1,1,1
endlayer


layer
1,1,1,1,1,1,1,1,1,1,1,1,1,1,1,1,0,1,1,1,1,0,0,1,1,1,0,1,1,1,1,1,1,1,1,1,1,1,1,1,1,1,1,1,1,1,1,1,1,1
1,1,1,1,1,1,1,1,1,1,1,1,1,1,1,0,0,0,0,0,0,0,0,0,0,0,0,0,1,1,0,0,0,1,1,1,1,1,1,0,1,1,1,1,1,1,1,1,1,1
1,1,1,1,1,1,1,1,1,1,1,1,1,1,1,0,0,0,9,0,0,0,0,0,0,0,0,0,1,1,1,0,1,1,1,1,1,1,1,0,0,1,1,1,1,1,1,1,1,1
1,1,1,1,0,0,0,1,1,1,1,1,1,1,0,0,0,0,9,0,0,0,2,9,9,9,0,0,1,1,0,0,1,1,1,0,0,0,0,0,0,1,1,1,1,1,1,1,1,1
1,1,1,1,1,0,0,0,0,0,0,1,1,1,0,9,0,0,2,0,0,0,0,2,0,0,0,0,0,0,0,0,0,0,0,0,0,0,0,0,0,1,1,1,1,1,1,1,1,1
1,1,1,1,1,1,0,0,0,9,9,0,1,1,0,9,9,9,0,0,0,0,0,0,0,0,0,0,0,0,0,0,0,0,0,9,0,0,0,0,1,1,1,1,1,1,1,1,1,1
1,1,1,1,1,1,1,0,0,9,9,2,1,1,0,2,2,2,0,0,0,0,0,0,0,0,0,0,0,0,0,0,0,0,9,9,0,0,0,1,1,1,1,1,1,1,0,1,1,1
1,1,1,1,1,1,1,0,0,9,9,9,0,0,0,0,0,0,0,0,0,0,0,0,0,0,0,0,0,0,0,0,0,2,9,9,0,0,0,1,1,1,1,1,0,0,1,1,1,1
1,1,1,1,1,1,1,1,0,0,9,9,0,0,0,0,0,0,0,0,0,0,0,0,0,0,0,0,0,0,0,0,0,0,0,2,9,9,0,1,1,1,0,0,0,0,1,1,1,1
1,1,1,0,0,1,1,1,1,0,9,9,0,0,0,0,0,0,0,0,0,0,0,0,0,0,0,0,0,0,0,0,0,0,0,0,2,2,0,0,0,0,0,0,0,1,1,1,1,1
1,1,1,1,0,1,1,1,1,0,9,2,0,0,0,0,0,0,0,0,0,0,0,0,0,0,0,0,0,0,0,0,0,0,0,0,0,0,0,9,9,9,9,0,0,1,1,1,1,1
1,1,1,1,1,0,9,0,9,9,9,0,0,0,0,0,0,0,0,0,0,0,0,0,0,0,0,0,0,0,0,0,0,0,0,0,0,0,0,2,0,0,0,0,0,0,1,1,1,1
1,1,1,1,1,0,9,9,9,9,0,0,0,0,0,0,0,0,0,0,0,0,0,0,0,0,0,0,0,0,0,0,0,0,0,0,0,0,0,0,0,0,0,0,0,0,1,1,1,1
1,0,0,0,0,0,9,9,2,0,0,0,0,0,0,0,0,0,0,0,0,0,0,0,0,0,0,0,0,0,0,0,0,0,0,0,0,0,0,0,0,0,0,9,0,0,1,1,1,1
1,1,0,9,9,2,2,0,0,0,0,0,0,0,0,0,0,0,0,0,0,0,0,0,0,0,0,0,0,0,0,0,0,0,0,0,0,0,0,0,0,9,9,0,0,0,1,1,1,1
1,0,0,0,0,0,0,0,0,0,0,0,0,0,0,0,0,0,0,0,0,0,0,0,0,0,0,0,0,0,0,0,0,0,0,0,0,0,0,2,2,0,0,0,0,0,1,1,1,1
1,1,1,1,0,0,0,0,0,0,0,0,0,0,0,0,0,0,0,0,0,0,0,0,0,0,0,0,0,0,0,0,0,0,0,0,0,0,0,0,0,0,0,0,9,0,0,1,1,1
1,1,1,1,0,0,0,0,0,0,0,0,0,0,0,0,0,0,0,0,0,0,0,0,0,0,0,0,0,0,0,0,0,0,0,0,0,0,0,0,0,0,0,2,9,0,0,0,1,1
1,1,0,1,0,0,0,0,0,0,0,0,0,0,0,0,0,0,0,0,0,0,0,0,0,0,0,0,0,0,0,0,0,0,0,0,0,0,0,0,0,0,0,0,9,9,0,1,1,1
0,0,0,0,0,0,0,0,0,0,0,0,0,0,0,0,0,0,0,0,0,0,0,0,0,0,0,0,0,0,0,0,0,0,0,0,0,0,0,0,0,0,0,0,9,0,0,1,1,1
0,0,0,0,0,0,0,0,0,0,0,0,0,0,0,0,0,0,0,0,0,0,0,0,0,0,0,0,0,0,0,0,0,0,0,0,0,0,0,0,0,0,0,2,9,0,0,1,1,1
0,0,0,9,9,2,0,0,0,0,0,0,0,0,0,0,0,0,0,0,0,0,0,0,0,0,0,0,0,0,0,0,0,0,0,0,0,0,0,0,0,0,0,2,9,0,0,0,1,1
1,0,0,0,9,2,0,0,0,0,0,0,0,0,0,0,0,0,0,0,0,0,0,0,0,0,0,0,0,0,0,0,0,0,0,0,0,0,0,0,0,0,0,9,9,9,0,0,0,1
1,1,1,0,9,0,0,0,0,0,0,0,0,0,0,0,0,0,0,0,0,0,0,0,0,0,0,0,0,0,0,0,0,0,0,0,0,0,0,0,0,0,0,0,9,9,0,0,0,1
1,1,0,0,0,0,0,0,0,0,0,0,0,0,0,0,0,0,0,0,0,0,0,0,0,0,0,0,0,0,0,0,0,0,0,0,0,0,0,0,0,0,0,0,9,0,0,0,1,1
1,1,0,0,9,0,0,0,0,0,0,0,0,0,0,0,0,0,0,0,0,0,0,0,0,0,0,0,0,0,0,0,0,0,0,0,0,0,0,0,0,0,0,0,9,0,0,0,0,1
1,1,1,0,9,0,0,0,0,0,0,0,0,0,0,0,0,0,0,0,0,0,0,0,0,0,0,0,0,0,0,0,0,0,0,0,0,0,0,0,0,0,0,0,0,9,9,0,0,1
1,1,0,0,0,0,0,0,0,0,0,0,0,0,0,0,0,0,0,0,0,0,0,0,0,0,0,0,0,0,0,0,0,0,0,0,0,0,0,0,0,0,0,0,0,0,0,0,1,1
0,0,0,9,2,0,0,0,0,0,0,0,0,0,0,0,0,0,0,0,0,0,0,0,0,0,0,0,0,0,0,0,0,0,0,0,0,0,0,0,0,0,0,0,0,0,1,1,1,1
1,1,0,0,0,0,0,0,0,0,0,0,0,0,0,0,0,0,0,0,0,0,0,0,0,0,0,0,0,0,0,0,0,0,0,0,0,0,0,0,0,0,0,0,0,1,1,1,1,1
1,1,1,0,0,0,0,0,0,0,0,0,0,0,0,0,0,0,0,0,0,0,0,0,0,0,0,0,0,0,0,0,0,0,0,0,0,0,0,0,0,0,0,0,0,1,0,0,1,1
1,1,1,0,0,0,9,2,0,0,0,0,0,0,0,0,0,0,0,0,0,0,0,0,0,0,0,0,0,0,0,0,0,0,0,0,0,0,0,0,0,0,0,0,0,2,9,0,0,1
1,0,0,0,0,0,0,9,2,0,0,0,0,0,0,0,0,0,0,0,0,0,0,0,0,0,0,0,0,0,0,0,0,0,0,0,0,0,0,0,0,0,0,0,2,0,0,0,0,1
1,1,1,1,1,0,0,0,9,0,0,0,0,0,0,0,0,0,0,0,0,0,0,0,0,0,0,0,0,0,0,0,0,0,0,0,0,0,0,0,0,0,0,0,9,0,0,1,1,1
1,1,1,1,1,1,0,0,0,0,0,0,0,0,0,0,0,0,0,0,0,0,0,0,0,0,0,0,0,0,0,0,0,0,0,0,0,0,0,0,0,0,0,0,0,0,0,1,1,1
1,1,1,1,1,1,0,0,0,0,0,0,0,0,0,0,0,0,0,0,0,0,0,0,0,0,0,0,0,0,0,0,0,0,0,0,0,0,0,0,0,0,9,9,0,0,0,0,1,1
1,1,1,1,1,1,0,0,0,0,0,0,0,0,0,0,0,0,0,0,0,0,0,0,0,0,0,0,0,0,0,0,0,0,0,0,0,0,0,0,0,0,9,9,0,0,1,0,0,1
1,1,1,1,0,0,1,1,1,1,0,0,0,0,0,0,0,0,0,0,0,0,0,0,0,0,0,0,0,0,0,0,0,0,0,0,0,0,0,0,0,0,0,0,0,1,1,1,1,1
1,1,1,1,1,1,1,1,1,1,0,0,0,0,0,0,0,0,0,0,0,0,0,0,0,0,0,0,0,0,0,0,0,0,0,0,0,0,0,0,0,0,1,0,0,1,1,1,1,1
1,1,1,1,1,1,1,1,1,0,9,9,0,0,0,0,0,0,0,0,0,0,0,0,0,0,0,0,0,0,0,0,0,0,0,0,0,0,2,2,0,1,1,1,1,1,1,1,1,1
1,1,1,1,1,1,1,1,0,0,0,0,0,0,0,0,0,0,0,0,0,0,0,0,0,0,0,0,0,0,0,0,0,0,0,0,0,0,9,9,9,0,1,1,1,1,1,1,1,1
1,1,1,1,1,1,0,0,0,0,0,0,9,9,9,0,0,0,0,0,0,0,0,0,0,0,0,0,0,0,0,0,0,0,0,0,2,2,9,0,0,9,1,1,1,1,1,1,1,1
1,1,1,1,0,1,1,1,0,0,1,1,0,0,0,9,0,0,0,0,0,0,0,0,0,0,0,0,0,0,0,0,2,2,2,2,9,9,0,0,0,0,0,1,1,1,1,1,1,1
1,1,1,1,1,1,1,0,0,1,1,1,0,0,0,0,0,0,2,0,0,0,0,0,0,0,0,0,0,0,2,0,9,9,9,9,9,0,0,1,1,0,0,1,1,1,1,1,1,1
1,1,1,1,1,0,1,1,1,1,1,1,1,0,0,0,9,0,0,0,0,2,0,0,0,0,2,2,0,0,9,9,9,0,0,0,0,0,0,1,1,1,0,0,1,1,1,1,1,1
1,1,1,1,1,1,1,1,1,1,1,1,0,0,0,0,0,0,0,0,9,2,0,0,0,0,9,9,0,2,0,0,0,0,0,0,0,0,0,1,1,1,1,0,0,1,1,1,1,1
1,1,1,1,1,1,1,1,1,1,1,0,0,0,1,1,1,1,0,0,0,0,9,0,0,0,9,0,9,9,9,9,0,0,0,1,1,1,0,1,1,1,1,1,1,1,1,1,1,1
1,1,1,1,1,1,1,1,1,1,1,1,0,1,1,1,1,1,0,0,0,0,0,9,0,1,0,0,0,0,0,9,0,1,1,1,1,1,1,1,1,1,1,1,1,1,1,1,1,1
1,1,1,1,1,1,1,1,1,1,1,1,1,1,1,1,1,1,0,0,1,1,0,0,1,1,0,0,0,0,0,0,0,1,1,1,1,1,1,1,1,1,1,1,1,1,1,1,1,1
1,1,1,1,1,1,1,1,1,1,1,1,1,1,1,1,1,1,1,1,1,1,0,1,1,1,1,1,1,1,1,1,1,1,1,1,1,1,1,1,1,1,1,1,1,1,1,1,1,1
endlayer

